<?xml version="1.0" encoding="utf-8"?>
<!-- This URDF was automatically created by SolidWorks to URDF Exporter! Originally created by Stephen Brawner (brawner@gmail.com) 
     Commit Version: 1.6.0-4-g7f85cfe  Build Version: 1.6.7995.38578
     For more information, please see http://wiki.ros.org/sw_urdf_exporter -->
<robot
  name="Manipulator_station_urdf_2">
  <link
    name="Base_link">
    <inertial>
      <origin
        xyz="-0.0723308343849347 -5.76034482321908E-07 -0.138936926425514"
        rpy="0 0 0" />
      <mass
        value="10.0719247157871" />
      <inertia
        ixx="0.225372672640189"
        ixy="-5.47722770076954E-09"
        ixz="6.39304001370768E-06"
        iyy="0.215329726186438"
        iyz="-1.29340124552014E-07"
        izz="0.191427829854737" />
    </inertial>
    <visual>
      <origin
        xyz="0 0 0"
        rpy="0 0 0" />
      <geometry>
        <mesh
          filename="file://$(find mani_p_description)/meshes/table_visual.STL" />
      </geometry>
      <material
        name="">
        <color
          rgba="0.792156862745098 0.819607843137255 0.933333333333333 1" />
      </material>
    </visual>
    <collision>
      <origin
        xyz="0 0 0"
        rpy="0 0 0" />
      <geometry>
        <mesh
          filename="file://$(find mani_p_description)/meshes/table_collision.STL" />
      </geometry>
    </collision>
  </link>
  <link
    name="Base_arm">
    <inertial>
      <origin
        xyz="-0.0413175046626831 -0.0208972801523338 0.0320669876730205"
        rpy="0 0 0" />
      <mass
        value="4.1228447557393" />
      <inertia
        ixx="0.0113726436801867"
        ixy="-0.000168232670470485"
        ixz="0.00126187574890212"
        iyy="0.00575937558728693"
        iyz="0.000203632637247424"
        izz="0.01188198101123" />
    </inertial>
    <visual>
      <origin
        xyz="0 0 0"
        rpy="0 0 0" />
      <geometry>
        <mesh
          filename="file://$(find mani_p_description)/meshes/Base_arm_visual.stl" />
      </geometry>
      <material
        name="">
        <color
          rgba="0.776470588235294 0.756862745098039 0.737254901960784 1" />
      </material>
    </visual>
    <collision>
      <origin
        xyz="0 0 0"
        rpy="0 0 0" />
      <geometry>
        <mesh
          filename="file://$(find mani_p_description)/meshes/base_collision.STL" />
      </geometry>
    </collision>
  </link>
  <joint
    name="Base_arm_J0"
    type="fixed">
    <origin
      xyz="0 0 0.04"
      rpy="0 0 0" />
    <parent
      link="Base_link" />
    <child
      link="Base_arm" />
    <axis
      xyz="0 0 -1" />
    <limit
      lower="-0.7"
      upper="0"
      effort="200"
      velocity="3" />
  </joint>
  <link
    name="L1">
    <inertial>
      <origin
        xyz="-1.10021436405816E-11 7.32518596352344E-05 0.0316911255153076"
        rpy="0 0 0" />
      <mass
        value="0.29717061581658" />
      <inertia
        ixx="0.000303886041407238"
        ixy="6.99241113621864E-15"
        ixz="4.48809908102748E-15"
        iyy="0.000133630920461156"
        iyz="3.51430414313121E-06"
        izz="0.000309461173077348" />
    </inertial>
    <visual>
      <origin
        xyz="0 0 0"
        rpy="0 0 0" />
      <geometry>
        <mesh
          filename="file://$(find mani_p_description)/meshes/L1_visual.stl" />
      </geometry>
      <material
        name="">
        <color
          rgba="0.792156862745098 0.819607843137255 0.933333333333333 1" />
      </material>
    </visual>
    <collision>
      <origin
        xyz="0 0 0"
        rpy="0 0 0" />
      <geometry>
        <mesh
          filename="file://$(find mani_p_description)/meshes/L1.STL" />
      </geometry>
    </collision>
  </link>
  <joint
    name="J1"
    type="revolute">
    <origin
      xyz="0 0 0.116000000000001"
      rpy="0 0 3.14159265358979" />
    <parent
      link="Base_arm" />
    <child
      link="L1" />
    <axis
      xyz="0 0 -1" />
    <limit
      lower="-1.57"
      upper="1.57"
      effort="200"
      velocity="3" />
  </joint>
  <link
    name="L2">
    <inertial>
      <origin
        xyz="0.20185150893891 0.0161645619972203 -7.55770843141323E-05"
        rpy="0 0 0" />
      <mass
        value="0.524148568163614" />
      <inertia
        ixx="0.000499774464110963"
        ixy="3.40054540308558E-06"
        ixz="-2.50463813782652E-06"
        iyy="0.000697225471781578"
        iyz="-2.48498255392067E-06"
        izz="0.000526429291456387" />
    </inertial>
    <visual>
      <origin
        xyz="0 0 0"
        rpy="0 0 0" />
      <geometry>
        <mesh
          filename="file://$(find mani_p_description)/meshes/L2_visual.stl" />
      </geometry>
      <material
        name="">
        <color
          rgba="0.792156862745098 0.819607843137255 0.933333333333333 1" />
      </material>
    </visual>
    <collision>
      <origin
        xyz="0 0 0"
        rpy="0 0 0" />
      <geometry>
        <mesh
          filename="file://$(find mani_p_description)/meshes/L2.STL" />
      </geometry>
    </collision>
  </link>
  <joint
    name="J2"
    type="revolute">
    <origin
      xyz="0 0 0.0330000000008923"
      rpy="1.5707963267949 -1.5707963267949 0" />
    <parent
      link="L1" />
    <child
      link="L2" />
    <axis
      xyz="0 0 -1" />
    <limit
      lower="-1.57"
      upper="1.57"
      effort="200"
      velocity="3" />
  </joint>
  <link
    name="L3">
    <inertial>
      <origin
        xyz="0.126152886971805 -0.0298818698825802 -0.000208214870130147"
        rpy="0 0 0" />
      <mass
        value="0.481103074710301" />
      <inertia
        ixx="0.000303413270297186"
        ixy="4.74930894283668E-06"
        ixz="4.09553375298929E-08"
        iyy="0.000668879602866701"
        iyz="-4.78878066581936E-08"
        izz="0.000667938888460889" />
    </inertial>
    <visual>
      <origin
        xyz="0 0 0"
        rpy="0 0 0" />
      <geometry>
        <mesh
          filename="file://$(find mani_p_description)/meshes/L3_visual.stl" />
      </geometry>
      <material
        name="">
        <color
          rgba="0.792156862745098 0.819607843137255 0.933333333333333 1" />
      </material>
    </visual>
    <collision>
      <origin
        xyz="0 0 0"
        rpy="0 0 0" />
      <geometry>
        <mesh
          filename="file://$(find mani_p_description)/meshes/L3.STL" />
      </geometry>
    </collision>
  </link>
  <joint
    name="J3"
    type="revolute">
    <origin
      xyz="0.264000000000014 0.0299999999999664 0"
      rpy="0 0 0.7854" />
    <parent
      link="L2" />
    <child
      link="L3" />
    <axis
      xyz="0 0 -1" />
    <limit
      lower="-2.3562"
      upper="1.57"
      effort="200"
      velocity="3" />
  </joint>
  <link
    name="L4">
    <inertial>
      <origin
        xyz="0.000100097952944411 -0.00166222902026096 -0.0538849440312941"
        rpy="0 0 0" />
      <mass
        value="0.0852756037730973" />
      <inertia
        ixx="3.19354778364782E-05"
        ixy="1.01420009491847E-06"
        ixz="2.04206635751293E-11"
        iyy="1.50843843290278E-05"
        iyz="-2.23825574257021E-11"
        izz="3.23539402730483E-05" />
    </inertial>
    <visual>
      <origin
        xyz="0 0 0"
        rpy="0 0 0" />
      <geometry>
        <mesh
          filename="file://$(find mani_p_description)/meshes/L4_visual.stl" />
      </geometry>
      <material
        name="">
        <color
          rgba="0.792156862745098 0.819607843137255 0.933333333333333 1" />
      </material>
    </visual>
    <collision>
      <origin
        xyz="0 0 0"
        rpy="0 0 0" />
      <geometry>
        <mesh
          filename="file://$(find mani_p_description)/meshes/L4.STL" />
      </geometry>
    </collision>
  </link>
  <joint
    name="J4"
    type="revolute">
    <origin
      xyz="0.294599574521192 -0.0300010233346771 0"
      rpy="1.5707963267949 0 1.5707963267949" />
    <parent
      link="L3" />
    <child
      link="L4" />
    <axis
      xyz="0 0 -1" />
    <limit
      lower="-1.57"
      upper="1.57"
      effort="200"
      velocity="3" />
  </joint>
  <link
    name="L5">
    <inertial>
      <origin
        xyz="0.0648173973448019 -0.000207323517899316 0.000713506973517346"
        rpy="0 0 0" />
      <mass
        value="0.138634418013041" />
      <inertia
        ixx="4.40601102397039E-05"
        ixy="-2.23466572762377E-07"
        ixz="1.74333782378955E-08"
        iyy="6.66828144588062E-05"
        iyz="1.71937506116129E-10"
        izz="6.22589621626479E-05" />
    </inertial>
    <visual>
      <origin
        xyz="0 0 0"
        rpy="0 0 0" />
      <geometry>
        <mesh
          filename="file://$(find mani_p_description)/meshes/L5_visual.stl" />
      </geometry>
      <material
        name="">
        <color
          rgba="0.792156862745098 0.819607843137255 0.933333333333333 1" />
      </material>
    </visual>
    <collision>
      <origin
        xyz="0 0 0"
        rpy="0 0 0" />
      <geometry>
        <mesh
          filename="file://$(find mani_p_description)/meshes/L5.STL" />
      </geometry>
    </collision>
  </link>
  <joint
    name="J5"
    type="revolute">
    <origin
      xyz="0.000180609076408655 -0.00300457659950193 -0.0491995745209299"
      rpy="1.63069405070014 -1.5707963267949 0" />
    <parent
      link="L4" />
    <child
      link="L5" />
    <axis
      xyz="0 0 -1" />
    <limit
      lower="-1.57"
      upper="1.57"
      effort="200"
      velocity="3" />
  </joint>

  <link
    name="palm_link">
    <inertial>
      <origin
        xyz="-0.00226453024192438 -0.0010248009627208 0.0584194430678014"
        rpy="0 0 0" />
      <mass
        value="0.289701061638163" />
      <inertia
        ixx="0.000485715302932963"
        ixy="8.80599267937846E-07"
        ixz="2.55613195626725E-07"
        iyy="0.000355003529337741"
        iyz="2.52975039528034E-06"
        izz="0.000204460007961112" />
    </inertial>
    <visual>
      <origin
        xyz="0 0 0"
        rpy="0 0 0" />
      <geometry>
        <mesh
          filename="file://$(find mani_p_description)/meshes/palm_link_visual.stl" />
      </geometry>
      <material
        name="">
        <color
          rgba="0.792156862745098 0.819607843137255 0.933333333333333 1" />
      </material>
    </visual>
    <collision>
      <origin
        xyz="0 0 0"
        rpy="0 0 0" />
      <geometry>
        <mesh
          filename="file://$(find mani_p_description)/meshes/palm_link.STL" />
      </geometry>
    </collision>
  </link>
  <joint
    name="palm_joint"
    type="revolute">
    <origin
      xyz="0.122 0 0"
      rpy="1.5707963267949 0 1.5707963267949" />
    <parent
      link="L5" />
    <child
      link="palm_link" />
    <axis
      xyz="0 0 1" />
    <limit
      lower="-1.517"
      upper="1.517"
      effort="0"
      velocity="0" />
  </joint>
  
  <link
    name="finger_bottom_r">
    <inertial>
      <origin
        xyz="-1.57504804709774E-06 0.0103477687962485 -0.0179072505006844"
        rpy="0 0 0" />
      <mass
        value="0.0390904842532838" />
      <inertia
        ixx="1.11750119733812E-05"
        ixy="2.00381580074309E-10"
        ixz="1.53980568888076E-15"
        iyy="4.24858636291947E-06"
        iyz="7.33897309644584E-11"
        izz="1.22231032107977E-05" />
    </inertial>
    <visual>
      <origin
        xyz="0 0 0"
        rpy="0 0 0" />
      <geometry>
        <mesh
          filename="file://$(find mani_p_description)/meshes/finger_bottom_r_visual.stl" />
      </geometry>
      <material
        name="">
        <color
          rgba="0.792156862745098 0.819607843137255 0.933333333333333 1" />
      </material>
    </visual>
  </link>
  <joint
    name="finger_bottom_joint_r"
    type="continuous">
    <origin
      xyz="0.0214999999999949 -0.0224507912842468 0.0905685556678659"
      rpy="-1.57079632679332 -1.51256983859285 -1.57079632679648" />
    <parent
      link="palm_link" />
    <child
      link="finger_bottom_r" />
    <axis
      xyz="0 0 -1" />
    <limit
      lower="0"
      upper="1.047"
      effort="0"
      velocity="0" />
  <mimic joint="finger_middle_joint_l" multiplier="-1" offset="0" />
  </joint>
  
  <link
    name="finger_link_br">
    <inertial>
      <origin
        xyz="-0.0105427929870295 0.153621112125587 0"
        rpy="0 0 0" />
      <mass
        value="0.149391152983794" />
      <inertia
        ixx="0.000157706124922853"
        ixy="4.11678888016498E-08"
        ixz="-7.7749176533443E-21"
        iyy="2.98941844520473E-05"
        iyz="7.09953835937379E-20"
        izz="0.000144295322039152" />
    </inertial>
    <visual>
      <origin
        xyz="0 0 0"
        rpy="0 0 0" />
      <geometry>
        <mesh
          filename="file://$(find mani_p_description)/meshes/finger_link_br.STL" />
      </geometry>
      <material
        name="">
        <color
          rgba="0.792156862745098 0.819607843137255 0.933333333333333 1" />
      </material>
    </visual>
    <collision>
      <origin
        xyz="0 0 0"
        rpy="0 0 0" />
      <geometry>
        <mesh
          filename="file://$(find mani_p_description)/meshes/finger_link_br.STL" />
      </geometry>
    </collision>
  </link>
  <joint
    name="finger_joint_br"
    type="continuous">
    <origin
      xyz="0 0.0719999999999685 -0.0275000000000003"
      rpy="3.1415926535897 0 1.51256983859285" />
    <parent
      link="finger_bottom_r" />
    <child
      link="finger_link_br" />
    <axis
      xyz="0 0 -1" />
  <mimic joint="finger_middle_joint_l" multiplier="-1" offset="0" />
  </joint>
  <link
    name="finger_bottom_l">
    <inertial>
      <origin
        xyz="-1.57429047786817E-06 0.0103477684253001 -0.0179072503770971"
        rpy="0 0 0" />
      <mass
        value="0.0390904840939087" />
      <inertia
        ixx="1.11750126407243E-05"
        ixy="2.00957003326503E-10"
        ixz="1.70849667176199E-14"
        iyy="4.24858623031579E-06"
        iyz="7.34108370994094E-11"
        izz="1.22231037404869E-05" />
    </inertial>
    <visual>
      <origin
        xyz="0 0 0"
        rpy="0 0 0" />
      <geometry>
        <mesh
          filename="file://$(find mani_p_description)/meshes/finger_bottom_l_visual.stl" />
      </geometry>
      <material
        name="">
        <color
          rgba="0.792156862745098 0.819607843137255 0.933333333333333 1" />
      </material>
    </visual>
  </link>
  <joint
    name="finger_bottom_joint_l"
    type="continuous">
    <origin
      xyz="0.0215000000000003 0.0225492087158531 0.0905685556674948"
      rpy="-1.570796326795 1.35374340392809 -1.570796326795" />
    <parent
      link="palm_link" />
    <child
      link="finger_bottom_l" />
    <axis
      xyz="0 0 -1" />
    <limit
      lower="-1.047"
      upper="0"
      effort="0"
      velocity="0" />
  <mimic joint="finger_middle_joint_l" multiplier="1" offset="0" />
  </joint>
  <link
    name="finger_link_bl">
    <inertial>
      <origin
        xyz="0.0105427929870561 0.153621112125734 1.37251321419285E-14"
        rpy="0 0 0" />
      <mass
        value="0.149391152983795" />
      <inertia
        ixx="0.000157706124922853"
        ixy="-4.1167888803679E-08"
        ixz="6.17283471983355E-20"
        iyy="2.98941844520473E-05"
        iyz="1.14579999242045E-19"
        izz="0.000144295322039152" />
    </inertial>
    <visual>
      <origin
        xyz="0 0 0"
        rpy="0 0 0" />
      <geometry>
        <mesh
          filename="file://$(find mani_p_description)/meshes/finger_link_bl.STL" />
      </geometry>
      <material
        name="">
        <color
          rgba="0.792156862745098 0.819607843137255 0.933333333333333 1" />
      </material>
    </visual>
    <collision>
      <origin
        xyz="0 0 0"
        rpy="0 0 0" />
      <geometry>
        <mesh
          filename="file://$(find mani_p_description)/meshes/finger_link_bl.STL" />
      </geometry>
    </collision>
  </link>
  <joint
    name="finger_joint_bl"
    type="continuous">
    <origin
      xyz="0 0.0719999999999986 -0.0274999999999848"
      rpy="-3.14159265358977 0 -1.35374340392809" />
    <parent
      link="finger_bottom_l" />
    <child
      link="finger_link_bl" />
    <axis
      xyz="0 0 -1" />
  <mimic joint="finger_middle_joint_l" multiplier="1" offset="0" />
  </joint>
  <link
    name="finger_middle_r">
    <inertial>
      <origin
        xyz="3.07531777821168E-14 0.0294314905526618 0.00116964140455819"
        rpy="0 0 0" />
      <mass
        value="0.0144050851692265" />
      <inertia
        ixx="6.19314750464424E-06"
        ixy="-1.55300843901116E-17"
        ixz="3.89228835506857E-20"
        iyy="1.57457222917256E-06"
        iyz="-8.62913815699304E-23"
        izz="4.8529856244746E-06" />
    </inertial>
    <visual>
      <origin
        xyz="0 0 0"
        rpy="0 0 0" />
      <geometry>
        <mesh
          filename="file://$(find mani_p_description)/meshes/finger_middle_r.STL" />
      </geometry>
      <material
        name="">
        <color
          rgba="0.792156862745098 0.819607843137255 0.933333333333333 1" />
      </material>
    </visual>
  </link>
  <joint
    name="finger_middle_joint_r"
    type="continuous">
    <origin
      xyz="-0.00599999999999851 -0.0224507912841861 0.15056855566751"
      rpy="-1.57079632679476 -1.35374340393146 -1.57079632679504" />
    <parent
      link="palm_link" />
    <child
      link="finger_middle_r" />
    <axis
      xyz="0 0 -1" />
  <mimic joint="finger_middle_joint_l" multiplier="-1" offset="0" />
  </joint>
  <link
    name="finger_middle_l">
    <inertial>
      <origin
        xyz="-4.38538094726937E-14 0.0294314905532609 0.00116964140455926"
        rpy="0 0 0" />
      <mass
        value="0.0144050851692265" />
      <inertia
        ixx="6.19314750464424E-06"
        ixy="5.11668780634681E-18"
        ixz="2.33758556857066E-20"
        iyy="1.57457222917255E-06"
        iyz="5.36483282785332E-21"
        izz="4.85298562447461E-06" />
    </inertial>
    <visual>
      <origin
        xyz="0 0 0"
        rpy="0 0 0" />
      <geometry>
        <mesh
          filename="file://$(find mani_p_description)/meshes/finger_middle_l.STL" />
      </geometry>
      <material
        name="">
        <color
          rgba="0.792156862745098 0.819607843137255 0.933333333333333 1" />
      </material>
    </visual>
  </link>
  <joint
    name="finger_middle_joint_l"
    type="revolute">
    <origin
      xyz="-0.00599999999999951 0.0225492087158556 0.150568555667489"
      rpy="-1.57079632679497 1.35374340393137 -1.57079632679498" />
    <parent
      link="palm_link" />
    <child
      link="finger_middle_l" />
    <axis
      xyz="0 0 -1" />
    <limit lower="-0.84901" upper="0.45099" effort="10.0" velocity="1.0" />
  </joint>
</robot>